<?xml version = "1.0" ?>
<robot name="WIP">

	<link name="link_chassis">

  <pose>0 0 0 0 0 0</pose>

  <inertial>
    <mass value="5"/>
    <origin rpy="0 0 0" xyz="0.3 0 0"/>
    <inertia ixx="0.0395416666667" ixy="0" ixz="0"     iyy="0.106208333333" iyz="0" izz="0.106208333333"/>
  </inertial>

  <collision name="collision_chassis">
    <geometry>
      <box size="0.1 0.3 1"/>
    </geometry>
  </collision>

  <visual>
   <origin rpy="0 0 0" xyz="0 0 0.3"/>
   <geometry>
     <box size="0.1 0.3 1"/>
   </geometry>
  </visual>
</link>

<link name="link_right_wheel">
  <inertial>
    <mass value="0.2"/>
    <origin rpy="0 1.5707 0" xyz="0 0 0"/>
    <inertia ixx="0.00052666666" ixy="0" ixz="0" iyy="0.00052666666" iyz="0" izz="0.001"/>
  </inertial>

  <collision name="link_right_wheel_collision">
    <origin rpy="0 1.5707 0" xyz="0 0 0" />
    <geometry>
      <cylinder length="0.1" radius="0.3"/>
    </geometry>
  </collision>

  <visual name="link_right_wheel_visual">
    <origin rpy="0 1.5707 1.5707" xyz="0 0.02 0"/>
    <geometry>
      <cylinder length="0.1" radius="0.3"/>
    </geometry>
  </visual>
</link>

<joint name="joint_right_wheel" type="continuous">
  <origin rpy="0 0 1.5707" xyz="0 0.2 0"/>
  <child link="link_right_wheel" />
  <parent link="link_chassis"/>
  <axis rpy="0 0 0" xyz="1 0 0"/>
  <limit effort="10000" velocity="1000"/>
  <joint_properties damping="1.0" friction="1.0" />
</joint>

<link name="link_left_wheel">
  <inertial>
    <mass value="0.2"/>
    <origin rpy="0 1.5707 0" xyz="0 0 0"/>
    <inertia ixx="0.00052666666" ixy="0" ixz="0" iyy="0.00052666666" iyz="0" izz="0.001"/>
  </inertial>

  <collision name="link_left_wheel_collision">
    <origin rpy="0 1.5707 0" xyz="0 0 0" />
    <geometry>
      <cylinder length="0.1" radius="0.3"/>
    </geometry>
  </collision>

  <visual name="link_left_wheel_visual">
    <origin rpy="0 1.5707 1.5707" xyz="0 0.02 0"/>
    <geometry>
      <cylinder length="0.1" radius="0.3"/>
    </geometry>
  </visual>
</link>

<joint name="joint_left_wheel" type="continuous">
  <origin rpy="0 0 1.5707" xyz="0 -0.2 0"/>
  <child link="link_left_wheel" />
  <parent link="link_chassis"/>
  <axis rpy="0 0 0" xyz="1 0 0"/>
  <limit effort="10000" velocity="1000"/>
  <joint_properties damping="1.0" friction="1.0" />
</joint>

</robot
